<?xml version="1.0" encoding="utf-8"?>
<!-- This URDF was automatically created by SolidWorks to URDF Exporter! Originally created by Stephen Brawner (brawner@gmail.com) 
     Commit Version: 1.6.0-1-g15f4949  Build Version: 1.6.7594.29634
     For more information, please see http://wiki.ros.org/sw_urdf_exporter -->
<robot
  name="Beo_Arm_M4">
  <link
    name="link_1">
    <inertial>
      <origin
        xyz="-0.0385731163984192 -2.28362687350156E-18 -0.00524859501374039"
        rpy="0 0 0" />
      <mass
        value="0.323605809581169" />
      <inertia
        ixx="0.000161147613159255"
        ixy="7.52991643291585E-22"
        ixz="-8.44321479741366E-06"
        iyy="0.000450631135476571"
        iyz="-4.38639332559304E-21"
        izz="0.000418295360654488" />
    </inertial>
    <visual>
      <origin
        xyz="0 0 0"
        rpy="0 0 0" />
      <geometry>
        <mesh
          filename="package://Beo_Arm_M4/meshes/link_1.STL" />
      </geometry>
      <material
        name="">
        <color
          rgba="0.792156862745098 0.819607843137255 0.933333333333333 1" />
      </material>
    </visual>
    <collision>
      <origin
        xyz="0 0 0"
        rpy="0 0 0" />
      <geometry>
        <mesh
          filename="package://Beo_Arm_M4/meshes/link_1.STL" />
      </geometry>
    </collision>
  </link>
  <link
    name="link_2">
    <inertial>
      <origin
        xyz="-0.0227815027756187 -4.6281880237975E-17 0.019"
        rpy="0 0 0" />
      <mass
        value="0.0178646986447077" />
      <inertia
        ixx="5.52910048182243E-06"
        ixy="-3.25578289100872E-21"
        ixz="1.47722568095917E-20"
        iyy="3.44196286692543E-05"
        iyz="-1.77152884664489E-21"
        izz="3.24160176753154E-05" />
    </inertial>
    <visual>
      <origin
        xyz="0 0 0"
        rpy="0 0 0" />
      <geometry>
        <mesh
          filename="package://Beo_Arm_M4/meshes/link_2.STL" />
      </geometry>
      <material
        name="">
        <color
          rgba="0.792156862745098 0.819607843137255 0.933333333333333 1" />
      </material>
    </visual>
    <collision>
      <origin
        xyz="0 0 0"
        rpy="0 0 0" />
      <geometry>
        <mesh
          filename="package://Beo_Arm_M4/meshes/link_2.STL" />
      </geometry>
    </collision>
  </link>
  <joint
    name="joint_1"
    type="continuous">
    <origin
      xyz="0 0 0.05"
      rpy="0 0 0.0029081091695893" />
    <parent
      link="link_1" />
    <child
      link="link_2" />
    <axis
      xyz="0 0 1" />
  </joint>
  <link
    name="link_3">
    <inertial>
      <origin
        xyz="0.121 -0.0315164899121854 9.0205620750794E-17"
        rpy="0 0 0" />
      <mass
        value="0.0649301185542534" />
      <inertia
        ixx="3.22586635547296E-05"
        ixy="-3.71552987546569E-20"
        ixz="3.32675498756577E-20"
        iyy="0.000476962065829219"
        iyz="1.97993951420693E-20"
        izz="0.000507342791034516" />
    </inertial>
    <visual>
      <origin
        xyz="0 0 0"
        rpy="0 0 0" />
      <geometry>
        <mesh
          filename="package://Beo_Arm_M4/meshes/link_3.STL" />
      </geometry>
      <material
        name="">
        <color
          rgba="0.792156862745098 0.819607843137255 0.933333333333333 1" />
      </material>
    </visual>
    <collision>
      <origin
        xyz="0 0 0"
        rpy="0 0 0" />
      <geometry>
        <mesh
          filename="package://Beo_Arm_M4/meshes/link_3.STL" />
      </geometry>
    </collision>
  </link>
  <joint
    name="joint_2"
    type="continuous">
    <origin
      xyz="0 0 0.019"
      rpy="3.14159265358979 -1.33277945223947 3.14159265358979" />
    <parent
      link="link_2" />
    <child
      link="link_3" />
    <axis
      xyz="0 1 0" />
  </joint>
  <link
    name="link_4">
    <inertial>
      <origin
        xyz="6.81676937119846E-14 -1.21539063535625E-16 0.14258"
        rpy="0 0 0" />
      <mass
        value="0.0575915155354546" />
      <inertia
        ixx="8.44653798915303E-05"
        ixy="-8.470329472543E-21"
        ixz="-3.45093709293554E-17"
        iyy="8.87747106609762E-05"
        iyz="-1.88646810498843E-19"
        izz="1.22592484459502E-05" />
    </inertial>
    <visual>
      <origin
        xyz="0 0 0"
        rpy="0 0 0" />
      <geometry>
        <mesh
          filename="package://Beo_Arm_M4/meshes/link_4.STL" />
      </geometry>
      <material
        name="">
        <color
          rgba="0.752941176470588 0.752941176470588 0.752941176470588 1" />
      </material>
    </visual>
    <collision>
      <origin
        xyz="0 0 0"
        rpy="0 0 0" />
      <geometry>
        <mesh
          filename="package://Beo_Arm_M4/meshes/link_4.STL" />
      </geometry>
    </collision>
  </link>
  <joint
    name="joint_3"
    type="continuous">
    <origin
      xyz="0.242 0 0"
      rpy="-3.14159265358979 1.33415282254542 0" />
    <parent
      link="link_3" />
    <child
      link="link_4" />
    <axis
      xyz="0 1 0" />
  </joint>
  <link
    name="link_5">
    <inertial>
      <origin
        xyz="0.0396521859530979 -0.0124327235015845 0.00083405314659353"
        rpy="0 0 0" />
      <mass
        value="0.0347450565910971" />
      <inertia
        ixx="1.31106926757633E-05"
        ixy="-1.02182124980525E-05"
        ixz="-1.75204148380451E-06"
        iyy="4.45647693907995E-05"
        iyz="-3.64347767856079E-07"
        izz="5.41110161491232E-05" />
    </inertial>
    <visual>
      <origin
        xyz="0 0 0"
        rpy="0 0 0" />
      <geometry>
        <mesh
          filename="package://Beo_Arm_M4/meshes/link_5.STL" />
      </geometry>
      <material
        name="">
        <color
          rgba="0.792156862745098 0.819607843137255 0.933333333333333 1" />
      </material>
    </visual>
    <collision>
      <origin
        xyz="0 0 0"
        rpy="0 0 0" />
      <geometry>
        <mesh
          filename="package://Beo_Arm_M4/meshes/link_5.STL" />
      </geometry>
    </collision>
  </link>
  <joint
    name="joint_4"
    type="continuous">
    <origin
      xyz="0 0 0.28516"
      rpy="3.14159265358979 0.647647264330797 0" />
    <parent
      link="link_4" />
    <child
      link="link_5" />
    <axis
      xyz="0 1 0" />
  </joint>
  <link
    name="hand">
    <inertial>
      <origin
        xyz="0.0886274662275076 -8.78203759713259E-18 0.00365476427426814"
        rpy="0 0 0" />
      <mass
        value="0.0570006651942083" />
      <inertia
        ixx="5.60296956427746E-05"
        ixy="1.10564269396288E-19"
        ixz="-6.84651376810428E-05"
        iyy="0.000244454826346669"
        iyz="6.01393392550553E-20"
        izz="0.000227870946005548" />
    </inertial>
    <visual>
      <origin
        xyz="0 0 0"
        rpy="0 0 0" />
      <geometry>
        <mesh
          filename="package://Beo_Arm_M4/meshes/hand.STL" />
      </geometry>
      <material
        name="">
        <color
          rgba="0.792156862745098 0.819607843137255 0.933333333333333 1" />
      </material>
    </visual>
    <collision>
      <origin
        xyz="0 0 0"
        rpy="0 0 0" />
      <geometry>
        <mesh
          filename="package://Beo_Arm_M4/meshes/hand.STL" />
      </geometry>
    </collision>
  </link>
  <joint
    name="joint_5"
    type="fixed">
    <origin
      xyz="0.106 0.000140000000003387 0.014"
      rpy="0 0 0" />
    <parent
      link="link_5" />
    <child
      link="hand" />
    <axis
      xyz="0 0 0" />
  </joint>
</robot>